<mujoco model="custom_hand">
  <compiler angle="radian"/>

  <default>
    <geom contype="0" conaffinity="0"/>
    <default class="hand">
      <material specular="0.5" shininess="0.25"/>
      <joint axis="0 1 0" range="-6.28319 6.28319" armature="0.1"/>
      <general gaintype="fixed" biastype="affine" ctrlrange="-6.2831 6.2831" gainprm="2000" biasprm="0 -2000 -400"
        forcerange="-150 150"/>
      <default class="size3">
        <default class="size3_limited">
          <joint range="-3.1415 3.1415"/>
          <general ctrlrange="-3.1415 3.1415"/>
        </default>
      </default>
      <default class="size1">
        <general gainprm="500" biasprm="0 -500 -100" forcerange="-5 5"/>
      </default>
      <default class="visual">
        <geom type="mesh" contype="0" conaffinity="0" group="2"/>
      </default>
    </default>
  </default>

  <worldbody>
    <geom size="0.04 0.05 0.0125" pos="0 0 0.0125" type="box" rgba="0.3 0.3 0.3 1"/>
    <body name="thumb_cmc_aa_link" pos="-0.035 -0.03 0.025" quat="0.988771 0 -0.149438 0">
      <inertial pos="0 0 0.015" mass="0.02" diaginertia="1e-06 1e-06 1e-07"/>
      <joint name="thumb_cmc_aa" pos="0 0 0" axis="1 0 0" range="-1.5708 1.5708" damping="0.01" frictionloss="0.01"/>
      <geom size="0.008 0.015" pos="0 0 0.015" type="cylinder" rgba="0.7 0.7 0.7 1"/>
      <body name="thumb_cmc_fe_link" pos="0 0 0.03">
        <inertial pos="0 0 0.0175" mass="0.02" diaginertia="1e-06 1e-06 1e-07"/>
        <joint name="thumb_cmc_fe" pos="0 0 0" axis="0 1 0" range="-1.5708 1.5708" damping="0.01" frictionloss="0.01"/>
        <geom size="0.008 0.0175" pos="0 0 0.0175" type="cylinder" rgba="0.7 0.7 0.7 1"/>
        <body name="thumb_mcp_fe_link" pos="0 0 0.035">
          <inertial pos="0 0 0.0241667" mass="0.03" diaginertia="6.14167e-06 6.14167e-06 2e-07"/>
          <joint name="thumb_mcp_fe" pos="0 0 0" axis="1 0 0" range="-1.5708 1.5708" damping="0.01" frictionloss="0.01"/>
          <geom size="0.008 0.015" pos="0 0 0.015" type="cylinder" rgba="0.7 0.7 0.7 1"/>
          <geom size="0.009" pos="0 0 0.0425" rgba="0.2 0.4 0.8 1"/>
        </body>
      </body>
    </body>
    <body name="index_mcp_aa_link" pos="-0.025 0.04 0.025">
      <inertial pos="0 0 0.0175" mass="0.02" diaginertia="1e-06 1e-06 1e-07"/>
      <joint name="index_mcp_aa" pos="0 0 0" axis="1 0 0" range="-1.5708 1.5708" damping="0.01" frictionloss="0.01"/>
      <geom size="0.008 0.0175" pos="0 0 0.0175" type="cylinder" rgba="0.7 0.7 0.7 1"/>
      <body name="index_mcp_fe_link" pos="0 0 0.035">
        <inertial pos="0 0 0.015" mass="0.02" diaginertia="1e-06 1e-06 1e-07"/>
        <joint name="index_mcp_fe" pos="0 0 0" axis="1 0 0" range="-1.5708 1.5708" damping="0.01" frictionloss="0.01"/>
        <geom size="0.008 0.015" pos="0 0 0.015" type="cylinder" rgba="0.7 0.7 0.7 1"/>
        <body name="index_dip_fe_link" pos="0 0 0.03">
          <inertial pos="0 0 0.0208333" mass="0.03" diaginertia="5.26667e-06 5.26667e-06 2e-07"/>
          <joint name="index_dip_fe" pos="0 0 0" axis="1 0 0" range="-1.5708 1.5708" damping="0.01" frictionloss="0.01"/>
          <geom size="0.008 0.0125" pos="0 0 0.0125" type="cylinder" rgba="0.7 0.7 0.7 1"/>
          <geom size="0.009" pos="0 0 0.0375" rgba="0.2 0.4 0.8 1"/>
        </body>
      </body>
    </body>
    <body name="middle_mcp_aa_link" pos="0 0.04 0.025">
      <inertial pos="0 0 0.0175" mass="0.02" diaginertia="1e-06 1e-06 1e-07"/>
      <joint name="middle_mcp_aa" pos="0 0 0" axis="1 0 0" range="-1.5708 1.5708" damping="0.01" frictionloss="0.01"/>
      <geom size="0.008 0.0175" pos="0 0 0.0175" type="cylinder" rgba="0.7 0.7 0.7 1"/>
      <body name="middle_mcp_fe_link" pos="0 0 0.035">
        <inertial pos="0 0 0.015" mass="0.02" diaginertia="1e-06 1e-06 1e-07"/>
        <joint name="middle_mcp_fe" pos="0 0 0" axis="1 0 0" range="-1.5708 1.5708" damping="0.01" frictionloss="0.01"/>
        <geom size="0.008 0.015" pos="0 0 0.015" type="cylinder" rgba="0.7 0.7 0.7 1"/>
        <body name="middle_dip_fe_link" pos="0 0 0.03">
          <inertial pos="0 0 0.0208333" mass="0.03" diaginertia="5.26667e-06 5.26667e-06 2e-07"/>
          <joint name="middle_dip_fe" pos="0 0 0" axis="1 0 0" range="-1.5708 1.5708" damping="0.01" frictionloss="0.01"/>
          <geom size="0.008 0.0125" pos="0 0 0.0125" type="cylinder" rgba="0.7 0.7 0.7 1"/>
          <geom size="0.009" pos="0 0 0.0375" rgba="0.2 0.4 0.8 1"/>
        </body>
      </body>
    </body>
    <body name="ring_mcp_fe_link" pos="0.025 0.035 0.025">
      <inertial pos="0 0 0.0275" mass="0.03" diaginertia="7.1e-06 7.1e-06 2e-07"/>
      <joint name="ring_mcp_fe" pos="0 0 0" axis="1 0 0" range="-1.5708 1.5708" damping="0.01" frictionloss="0.01"/>
      <geom size="0.008 0.0175" pos="0 0 0.0175" type="cylinder" rgba="0.7 0.7 0.7 1"/>
      <geom size="0.009" pos="0 0 0.0475" rgba="0.2 0.4 0.8 1"/>
    </body>
  </worldbody>

  <actuator>
    <general class="size1" name="thumb_cmc_aa"   joint="thumb_cmc_aa"/>
    <general class="size1" name="thumb_cmc_fe"   joint="thumb_cmc_fe"/>
    <general class="size1" name="thumb_mcp_fe"   joint="thumb_mcp_fe"/>
    <general class="size1" name="index_mcp_aa"   joint="index_mcp_aa"/>
    <general class="size1" name="index_mcp_fe"   joint="index_mcp_fe"/>
    <general class="size1" name="index_dip_fe"   joint="index_dip_fe"/>
    <general class="size1" name="middle_mcp_aa"  joint="middle_mcp_aa"/>
    <general class="size1" name="middle_mcp_fe"  joint="middle_mcp_fe"/>
    <general class="size1" name="middle_dip_fe"  joint="middle_dip_fe"/>
    <general class="size1" name="ring_mcp_fe"    joint="ring_mcp_fe"/>
  </actuator>

</mujoco>
