<?xml version='1.0' encoding='utf-8'?>
<mujoco model="iiwa7_with_leap_right">
  <compiler angle="radian" meshdir="../meshes/visual" autolimits="true" />
  <!-- timestep/iterations/ls_iterations 등 solver 파라미터는 mujoco_simulator.yaml에서
       관리한다 (rtc_mujoco_sim ApplySolverConfig가 scene_*.xml에서만 <option>을 탐지하므로
       자식 모델의 <option>은 어차피 YAML로 덮어씌워짐). -->
  <option integrator="implicitfast" />

  <!-- ─── default classes (joint properties + position-servo PD SSoT) ─────────
       iiwa7: Panda 유사 class. proximal(J1-J4)이 큰 link 관성/토크 → 상향.
              PD gain은 ur5e MJCF 패턴(size3 kp=2000/kd=400, size1 kp=500/kd=100,
              ζ≈0.2)을 따르되 iiwa7 payload에 맞춰 1.5× 스케일:
                proximal kp=3000 kd=600, distal kp=750 kd=150.
       LEAP : XC430 gear 159.5:1, 고감속비 → reflected inertia 큼.
              MCP(flex) / PIP(abduction at base) / DIP(mid+tip) / thumb 4-tier.
              PD gain은 forcerange ±0.95 N·m 한계 하에서 보수적으로 kp=2.5 kd=0.125
              (이전 값의 1/4). forcerange는 XC430 stall 안전 한계 ±0.95로 유지.
       MANUAL: urdf_to_mjcf 재실행 시 이 블록 + 각 joint/actuator의 class 속성이
               사라집니다. 재주입할 것 (robots/iiwa7_leap/README.md). -->
  <default>
    <default class="iiwa7">
      <joint armature="0.2" damping="2.0" frictionloss="0.3" />
      <general gaintype="fixed" biastype="affine" forcerange="-200 200" />
      <default class="iiwa7_proximal">
        <joint armature="0.25" damping="3.0" frictionloss="0.5" />
        <general gainprm="3000" biasprm="0 -3000 -600" />
      </default>
      <default class="iiwa7_distal">
        <joint armature="0.15" damping="1.0" frictionloss="0.2" />
        <general gainprm="750" biasprm="0 -750 -150" />
      </default>
    </default>
    <default class="leap">
      <general gaintype="fixed" biastype="affine" gainprm="2.5"
               biasprm="0 -2.5 -0.125" forcerange="-0.95 0.95" />
      <default class="leap_mcp">
        <joint armature="0.006" damping="0.10" frictionloss="0.04" />
      </default>
      <default class="leap_pip">
        <joint armature="0.004" damping="0.06" frictionloss="0.025" />
      </default>
      <default class="leap_dip">
        <joint armature="0.003" damping="0.04" frictionloss="0.015" />
      </default>
      <default class="leap_thumb">
        <joint armature="0.006" damping="0.10" frictionloss="0.04" />
      </default>
    </default>
  </default>

  <asset>
    <mesh name="link_0" content_type="model/obj" file="link_0.obj" />
    <mesh name="link_1" content_type="model/obj" file="link_1.obj" />
    <mesh name="link_2" content_type="model/obj" file="link_2.obj" />
    <mesh name="link_3" content_type="model/obj" file="link_3.obj" />
    <mesh name="link_4" content_type="model/obj" file="link_4.obj" />
    <mesh name="link_5" content_type="model/obj" file="link_5.obj" />
    <mesh name="link_6" content_type="model/obj" file="link_6.obj" />
    <mesh name="link_7" content_type="model/obj" file="link_7.obj" />
    <mesh name="palm_lower" content_type="model/obj" file="palm_lower.obj" />
    <mesh name="mcp_joint" content_type="model/obj" file="mcp_joint.obj" />
    <mesh name="pip" content_type="model/obj" file="pip.obj" />
    <mesh name="dip" content_type="model/obj" file="dip.obj" />
    <mesh name="fingertip" content_type="model/obj" file="fingertip.obj" />
    <mesh name="white_tip" content_type="model/obj" file="white_tip.obj" />
    <mesh name="thumb_pip" content_type="model/obj" file="thumb_pip.obj" />
    <mesh name="thumb_dip" content_type="model/obj" file="thumb_dip.obj" />
    <mesh name="thumb_fingertip" content_type="model/obj" file="thumb_fingertip.obj" />
    <mesh name="white_tip_thumb" content_type="model/obj" file="white_tip_thumb.obj" />
  </asset>
  <!-- MANUAL: iiwa7 joint dynamics와 LEAP joint dynamics는 위 <default> class 블록의
       iiwa7_proximal / iiwa7_distal / leap_mcp / leap_pip / leap_dip / leap_thumb 가
       단일 출처(SSoT). urdf_to_mjcf 재실행 시 <default> 블록 + 각 joint의 class 속성이
       모두 사라지므로 재주입할 것 (left 동일). -->
  <worldbody>
    <body name="link_0">
      <inertial pos="-0.012857 0 0.069964" quat="0.444802 0.549682 0.549682 0.444802" mass="4.85566" diaginertia="0.022294 0.0215006 0.0176724" />
      <geom type="mesh" contype="0" conaffinity="0" group="1" density="0" mesh="link_0" />
      <geom type="mesh" mesh="link_0" />
      <body name="link_1" pos="0 0 0.1475">
        <inertial pos="0 -0.034819 0.123299" quat="0.700813 0.0941355 -0.0941355 0.700813" mass="3.39401" diaginertia="0.0214418 0.021383 0.00652421" />
        <joint name="A1" class="iiwa7_proximal" pos="0 0 0" axis="0 0 1" range="-2.96706 2.96706" actuatorfrcrange="-200 200" />
        <geom pos="0 0 -0.1475" type="mesh" contype="0" conaffinity="0" group="1" density="0" mesh="link_1" />
        <geom pos="0 0 -0.1475" type="mesh" mesh="link_1" />
        <body name="link_2" pos="0 -0.0105 0.1925">
          <inertial pos="0 0.039793 0.086944" quat="0.991454 0.130453 0 0" mass="4.03199" diaginertia="0.031697 0.031657 0.00808898" />
          <joint name="A2" class="iiwa7_proximal" pos="0 0 0" axis="0 1 0" range="-2.0944 2.0944" actuatorfrcrange="-200 200" />
          <geom pos="0 0.0105 -0.34" type="mesh" contype="0" conaffinity="0" group="1" density="0" mesh="link_2" />
          <geom pos="0 0.0105 -0.34" type="mesh" mesh="link_2" />
          <body name="link_3" pos="0 0.0105 0.2075">
            <inertial pos="0 0.034819 0.123299" quat="0.700813 -0.0941355 0.0941355 0.700813" mass="3.39401" diaginertia="0.0214418 0.021383 0.00652421" />
            <joint name="A3" class="iiwa7_proximal" pos="0 0 0" axis="0 0 1" range="-2.96706 2.96706" actuatorfrcrange="-200 200" />
            <geom pos="0 0 -0.5475" type="mesh" contype="0" conaffinity="0" group="1" density="0" mesh="link_3" />
            <geom pos="0 0 -0.5475" type="mesh" mesh="link_3" />
            <body name="link_4" pos="0 0.0105 0.1925">
              <inertial pos="0 -0.039793 0.086944" quat="0.991454 -0.130453 0 0" mass="4.03199" diaginertia="0.031695 0.031656 0.00808798" />
              <joint name="A4" class="iiwa7_proximal" pos="0 0 0" axis="0 -1 0" range="-2.0944 2.0944" actuatorfrcrange="-200 200" />
              <geom pos="0 -0.0105 -0.74" type="mesh" contype="0" conaffinity="0" group="1" density="0" mesh="link_4" />
              <geom pos="0 -0.0105 -0.74" type="mesh" mesh="link_4" />
              <body name="link_5" pos="0 -0.0105 0.2075">
                <inertial pos="0 -0.029824 0.076267" quat="0.683304 0.181923 -0.181923 0.683304" mass="1.52924" diaginertia="0.00874413 0.008485 0.00223987" />
                <joint name="A5" class="iiwa7_distal" pos="0 0 0" axis="0 0 1" range="-2.96706 2.96706" actuatorfrcrange="-200 200" />
                <geom pos="0 0 -0.9475" quat="1 0 0 0" type="mesh" contype="0" conaffinity="0" group="1" density="0" mesh="link_5" />
                <geom pos="0 0 -0.9475" quat="1 0 0 0" type="mesh" mesh="link_5" />
                <body name="link_6" pos="0 -0.0707 0.1925">
                  <inertial pos="0 0.07102 0.00495" quat="0.997576 0.0695794 0 0" mass="2.40363" diaginertia="0.007067 0.0068476 0.0045854" />
                  <joint name="A6" class="iiwa7_distal" pos="0 0 0" axis="0 1 0" range="-2.0944 2.0944" actuatorfrcrange="-200 200" />
                  <geom pos="0 0.0707 -1.14" type="mesh" contype="0" conaffinity="0" group="1" density="0" mesh="link_6" />
                  <geom pos="0 0.0707 -1.14" type="mesh" mesh="link_6" />
                  <body name="link_7" pos="0 0.0707 0.091">
                    <inertial pos="3e-06 -2e-06 0.013782" quat="0.5 0.5 -0.5 0.5" mass="0.259474" diaginertia="0.000299 0.000171 0.000171" />
                    <joint name="A7" class="iiwa7_distal" pos="0 0 0" axis="0 0 1" range="-3.05433 3.05433" actuatorfrcrange="-200 200" />
                    <geom pos="0 0 -1.231" quat="1 0 0 0" type="mesh" contype="0" conaffinity="0" group="1" density="0" mesh="link_7" />
                    <geom pos="0 0 -1.231" quat="1 0 0 0" type="mesh" mesh="link_7" />
                    <body name="ee_link" pos="0 0 0.035" quat="0.707109 0 -0.707105 0">
                      <body name="base" pos="0.005 0 0" quat="0.707107 0 0.707107 0">
                        <body name="palm_lower" pos="0 0.038 0.098" quat="0.707109 0 -0.707105 0">
                          <inertial pos="0 0 0" quat="0.497095 0.495942 -0.509424 0.497419" mass="0.237" diaginertia="0.000529322 0.000354076 0.000260868" />
                          <geom pos="-0.02 0.02575 -0.0347" quat="1 0 0 0" type="mesh" contype="0" conaffinity="0" group="1" density="0" mesh="palm_lower" />
                          <geom size="0.011 0.013 0.017" pos="-0.009 0.008 -0.011" type="box" />
                          <geom size="0.011 0.013 0.017" pos="-0.009 -0.037 -0.011" type="box" />
                          <geom size="0.011 0.013 0.017" pos="-0.009 -0.082 -0.011" type="box" />
                          <geom size="0.029 0.01 0.023" pos="-0.066 -0.078 -0.0115" quat="0.989016 0 0 -0.147806" type="box" />
                          <geom size="0.01 0.06 0.015" pos="-0.03 -0.035 -0.003" type="box" />
                          <geom size="0.005 0.06 0.01" pos="-0.032 -0.035 -0.024" quat="0.923956 0 0.382499 0" type="box" />
                          <geom size="0.012 0.058 0.023" pos="-0.048 -0.033 -0.0115" type="box" />
                          <geom size="0.022 0.026 0.023" pos="-0.078 -0.053 -0.0115" type="box" />
                          <geom size="0.002 0.018 0.017" pos="-0.098 -0.009 -0.006" type="box" />
                          <geom size="0.022 0.028 0.002" pos="-0.078 -0.003 0.01" type="box" />
                          <body name="mcp_joint" pos="-0.007 0.023 -0.0187" quat="0.500003 0.5 0.5 -0.499997">
                            <inertial pos="0 0 0" quat="0.388585 0.626468 -0.324549 0.592628" mass="0.044" diaginertia="1.47756e-05 1.31982e-05 6.0802e-06" />
                            <joint name="1" class="leap_mcp" pos="0 0 0" axis="0 0 -1" range="-0.314 2.23" actuatorfrcrange="-0.95 0.95" />
                            <geom pos="0.0084 0.0077 0.01465" quat="1 0 0 0" type="mesh" contype="0" conaffinity="0" group="1" density="0" mesh="mcp_joint" />
                            <geom size="0.01 0.003 0.017" pos="0 0.018 0.0147" type="box" />
                            <geom size="0.014 0.02 0.01" pos="-0.027 0.042 0.015" type="box" />
                            <geom size="0.017 0.003 0.01" pos="-0.0262 0.02 0.0146" type="box" />
                            <geom size="0.01 0.012 0.004" pos="-0.0295 0.035 0.029" type="box" />
                            <geom size="0.007 0.01 0.002" pos="0 0.005 0.03" type="box" />
                            <geom size="0.007 0.01 0.002" pos="0 0.005 -0.001" type="box" />
                            <body name="pip" pos="-0.0122 0.0381 0.0145" quat="0.500003 -0.5 -0.499997 0.5">
                              <inertial pos="0 0 0" quat="0.709913 0.704273 -0.000363156 0.00475427" mass="0.032" diaginertia="4.7981e-06 4.23406e-06 2.86184e-06" />
                              <joint name="0" class="leap_pip" pos="0 0 0" axis="0 0 -1" range="-1.047 1.047" actuatorfrcrange="-0.95 0.95" />
                              <geom pos="0.0096 0.0002 0.0007" quat="0.500003 -0.5 -0.5 -0.499997" type="mesh" contype="0" conaffinity="0" group="1" density="0" mesh="pip" />
                              <geom size="0.017 0.013 0.011" pos="0.0075 -0.0002 -0.011" type="box" />
                              <body name="dip" pos="0.015 0.0143 -0.013" quat="0.500003 0.5 -0.5 0.499997">
                                <inertial pos="0 0 0" quat="-0.252689 0.659216 0.238844 0.666735" mass="0.037" diaginertia="6.68256e-06 6.24841e-06 5.02002e-06" />
                                <joint name="2" class="leap_dip" pos="0 0 0" axis="0 0 -1" range="-0.506 1.885" actuatorfrcrange="-0.95 0.95" />
                                <geom pos="0.0211 -0.0084 0.0097" quat="2.67949e-08 -1 0 0" type="mesh" contype="0" conaffinity="0" group="1" density="0" mesh="dip" />
                                <geom size="0.008 0.003 0.013" pos="0 -0.02 0.015" type="box" />
                                <geom size="0.01 0.002 0.017" pos="0 -0.016 0.015" type="box" />
                                <geom size="0.007 0.01 0.002" pos="0 -0.0045 0.03" type="box" />
                                <geom size="0.007 0.01 0.002" pos="0 -0.0045 0" type="box" />
                                <geom size="0.017 0.011 0.013" pos="0.0075 -0.035 0.015" type="box" />
                                <body name="fingertip" pos="0 -0.0361 0.0002">
                                  <inertial pos="0 0 0" quat="0.706755 0.706755 0.0223155 0.0223155" mass="0.016" diaginertia="3.37527e-06 2.863e-06 1.54873e-06" />
                                  <joint name="3" class="leap_dip" pos="0 0 0" axis="0 0 -1" range="-0.366 2.042" actuatorfrcrange="-0.95 0.95" />
                                  <geom pos="0.0132 -0.0061 0.0144" quat="2.67949e-08 1 0 0" type="mesh" contype="0" conaffinity="0" group="1" density="0" mesh="fingertip" />
                                  <geom size="0.01 0.003 0.015" pos="0 -0.017 0.015" type="box" />
                                  <geom size="0.007 0.011 0.002" pos="0 -0.006 0.03" type="box" />
                                  <geom size="0.007 0.011 0.002" pos="0 -0.006 -0.001" type="box" />
                                  <geom type="mesh" mesh="white_tip" />
                                  <body name="index_tip_head" pos="0 -0.048 0.015" />
                                </body>
                              </body>
                            </body>
                          </body>
                          <body name="mcp_joint_2" pos="-0.0071 -0.0224 -0.0187" quat="0.500003 0.5 0.5 -0.499997">
                            <inertial pos="0 0 0" quat="0.388585 0.626468 -0.324549 0.592628" mass="0.044" diaginertia="1.47756e-05 1.31982e-05 6.0802e-06" />
                            <joint name="5" class="leap_mcp" pos="0 0 0" axis="0 0 -1" range="-0.314 2.23" actuatorfrcrange="-0.95 0.95" />
                            <geom pos="0.0084 0.0077 0.01465" quat="1 0 0 0" type="mesh" contype="0" conaffinity="0" group="1" density="0" mesh="mcp_joint" />
                            <geom size="0.01 0.003 0.017" pos="0 0.018 0.0147" type="box" />
                            <geom size="0.014 0.02 0.01" pos="-0.027 0.042 0.015" type="box" />
                            <geom size="0.017 0.003 0.01" pos="-0.0262 0.02 0.0146" type="box" />
                            <geom size="0.01 0.012 0.004" pos="-0.0295 0.035 0.029" type="box" />
                            <geom size="0.007 0.01 0.002" pos="0 0.005 0.03" type="box" />
                            <geom size="0.007 0.01 0.002" pos="0 0.005 -0.001" type="box" />
                            <body name="pip_2" pos="-0.0122 0.0381 0.0145" quat="0.500003 -0.5 -0.499997 0.5">
                              <inertial pos="0 0 0" quat="0.709913 0.704273 -0.000363156 0.00475427" mass="0.032" diaginertia="4.7981e-06 4.23406e-06 2.86184e-06" />
                              <joint name="4" class="leap_pip" pos="0 0 0" axis="0 0 -1" range="-1.047 1.047" actuatorfrcrange="-0.95 0.95" />
                              <geom pos="0.0096 0.0003 0.0007" quat="0.500003 -0.5 -0.5 -0.499997" type="mesh" contype="0" conaffinity="0" group="1" density="0" mesh="pip" />
                              <geom size="0.017 0.013 0.011" pos="0.0075 -0.0002 -0.011" type="box" />
                              <body name="dip_2" pos="0.015 0.0143 -0.013" quat="0.500003 0.5 -0.5 0.499997">
                                <inertial pos="0 0 0" quat="-0.252689 0.659216 0.238844 0.666735" mass="0.037" diaginertia="6.68256e-06 6.24841e-06 5.02002e-06" />
                                <joint name="6" class="leap_dip" pos="0 0 0" axis="0 0 -1" range="-0.506 1.885" actuatorfrcrange="-0.95 0.95" />
                                <geom pos="0.0211 -0.0084 0.0097" quat="1.32679e-06 -1 0 0" type="mesh" contype="0" conaffinity="0" group="1" density="0" mesh="dip" />
                                <geom size="0.008 0.003 0.013" pos="0 -0.02 0.015" type="box" />
                                <geom size="0.01 0.002 0.017" pos="0 -0.016 0.015" type="box" />
                                <geom size="0.007 0.01 0.002" pos="0 -0.0045 0.03" type="box" />
                                <geom size="0.007 0.01 0.002" pos="0 -0.0045 0" type="box" />
                                <geom size="0.017 0.011 0.013" pos="0.0075 -0.035 0.015" type="box" />
                                <body name="fingertip_2" pos="0 -0.0361 0.0002">
                                  <inertial pos="0 0 0" quat="0.706755 0.706755 0.0223155 0.0223155" mass="0.016" diaginertia="3.37527e-06 2.863e-06 1.54873e-06" />
                                  <joint name="7" class="leap_dip" pos="0 0 0" axis="0 0 -1" range="-0.366 2.042" actuatorfrcrange="-0.95 0.95" />
                                  <geom pos="0.0132 -0.0061 0.0145" quat="1.32679e-06 1 0 0" type="mesh" contype="0" conaffinity="0" group="1" density="0" mesh="fingertip" />
                                  <geom size="0.01 0.003 0.015" pos="0 -0.017 0.015" type="box" />
                                  <geom size="0.007 0.011 0.002" pos="0 -0.006 0.03" type="box" />
                                  <geom size="0.007 0.011 0.002" pos="0 -0.006 -0.001" type="box" />
                                  <geom type="mesh" mesh="white_tip" />
                                  <body name="middle_tip_head" pos="0 -0.048 0.015" />
                                </body>
                              </body>
                            </body>
                          </body>
                          <body name="mcp_joint_3" pos="-0.00709 -0.0678 -0.0187" quat="0.500003 0.5 0.5 -0.499997">
                            <inertial pos="0 0 0" quat="0.388585 0.626468 -0.324549 0.592628" mass="0.044" diaginertia="1.47756e-05 1.31982e-05 6.0802e-06" />
                            <joint name="9" class="leap_mcp" pos="0 0 0" axis="0 0 -1" range="-0.314 2.23" actuatorfrcrange="-0.95 0.95" />
                            <geom pos="0.0084 0.0077 0.01465" quat="1 0 0 0" type="mesh" contype="0" conaffinity="0" group="1" density="0" mesh="mcp_joint" />
                            <geom size="0.01 0.003 0.017" pos="0 0.018 0.0147" type="box" />
                            <geom size="0.014 0.02 0.01" pos="-0.027 0.042 0.015" type="box" />
                            <geom size="0.017 0.003 0.01" pos="-0.0262 0.02 0.0146" type="box" />
                            <geom size="0.01 0.012 0.004" pos="-0.0295 0.035 0.029" type="box" />
                            <geom size="0.007 0.01 0.002" pos="0 0.005 0.03" type="box" />
                            <geom size="0.007 0.01 0.002" pos="0 0.005 -0.001" type="box" />
                            <body name="pip_3" pos="-0.0122 0.0381 0.0145" quat="0.500003 -0.5 -0.499997 0.5">
                              <inertial pos="0 0 0" quat="0.709913 0.704273 -0.000363156 0.00475427" mass="0.032" diaginertia="4.7981e-06 4.23406e-06 2.86184e-06" />
                              <joint name="8" class="leap_pip" pos="0 0 0" axis="0 0 -1" range="-1.047 1.047" actuatorfrcrange="-0.95 0.95" />
                              <geom pos="0.0096 0.0003 0.0007" quat="0.500003 -0.5 -0.5 -0.499997" type="mesh" contype="0" conaffinity="0" group="1" density="0" mesh="pip" />
                              <geom size="0.017 0.013 0.011" pos="0.0075 -0.0002 -0.011" type="box" />
                              <body name="dip_3" pos="0.015 0.0143 -0.013" quat="0.500003 0.5 -0.5 0.499997">
                                <inertial pos="0 0 0" quat="-0.252689 0.659216 0.238844 0.666735" mass="0.037" diaginertia="6.68256e-06 6.24841e-06 5.02002e-06" />
                                <joint name="10" class="leap_dip" pos="0 0 0" axis="0 0 -1" range="-0.506 1.885" actuatorfrcrange="-0.95 0.95" />
                                <geom pos="0.0211 -0.0084 0.0097" quat="1.32679e-06 -1 0 0" type="mesh" contype="0" conaffinity="0" group="1" density="0" mesh="dip" />
                                <geom size="0.008 0.003 0.013" pos="0 -0.02 0.015" type="box" />
                                <geom size="0.01 0.002 0.017" pos="0 -0.016 0.015" type="box" />
                                <geom size="0.007 0.01 0.002" pos="0 -0.0045 0.03" type="box" />
                                <geom size="0.007 0.01 0.002" pos="0 -0.0045 0" type="box" />
                                <geom size="0.017 0.011 0.013" pos="0.0075 -0.035 0.015" type="box" />
                                <body name="fingertip_3" pos="0 -0.03609 0.0002">
                                  <inertial pos="0 0 0" quat="0.706755 0.706755 0.0223155 0.0223155" mass="0.016" diaginertia="3.37527e-06 2.863e-06 1.54873e-06" />
                                  <joint name="11" class="leap_dip" pos="0 0 0" axis="0 0 -1" range="-0.366 2.042" actuatorfrcrange="-0.95 0.95" />
                                  <geom pos="0.0132 -0.0061 0.0145" quat="1.32679e-06 1 0 0" type="mesh" contype="0" conaffinity="0" group="1" density="0" mesh="fingertip" />
                                  <geom size="0.01 0.003 0.015" pos="0 -0.017 0.015" type="box" />
                                  <geom size="0.007 0.011 0.002" pos="0 -0.006 0.03" type="box" />
                                  <geom size="0.007 0.011 0.002" pos="0 -0.006 -0.001" type="box" />
                                  <geom type="mesh" mesh="white_tip" />
                                  <body name="ring_tip_head" pos="0 -0.048 0.015" />
                                </body>
                              </body>
                            </body>
                          </body>
                          <body name="thumb_temp_base" pos="-0.0693 -0.0012 -0.0216" quat="0.707109 0 0.707105 0">
                            <inertial pos="0 0 0" quat="0.709913 0.704273 -0.000363156 0.00475427" mass="0.032" diaginertia="4.7981e-06 4.23406e-06 2.86184e-06" />
                            <joint name="12" class="leap_thumb" pos="0 0 0" axis="0 0 -1" range="-0.349 2.094" actuatorfrcrange="-0.95 0.95" />
                            <geom pos="-0.0053 0.0003 0.00078" quat="0.500003 -0.5 -0.5 -0.499997" type="mesh" contype="0" conaffinity="0" group="1" density="0" mesh="pip" />
                            <geom size="0.017 0.013 0.011" pos="0.0075 -0.0002 -0.011" type="box" />
                            <body name="thumb_pip" pos="0 0.0143 -0.013" quat="0.500003 0.5 -0.5 0.499997">
                              <inertial pos="0 0 0" mass="0.003" diaginertia="5.93e-07 5.49e-07 2.24e-07" />
                              <joint name="13" class="leap_thumb" pos="0 0 0" axis="0 0 -1" range="-0.47 2.443" actuatorfrcrange="-0.95 0.95" />
                              <geom pos="0.01196 0 -0.0158" quat="0.707109 0.707105 0 0" type="mesh" contype="0" conaffinity="0" group="1" density="0" mesh="thumb_pip" />
                              <geom size="0.009 0.0165 0.002" pos="0 0 -0.0015" type="box" />
                              <geom size="0.007 0.002 0.01" pos="0 -0.015 -0.013" type="box" />
                              <geom size="0.007 0.002 0.01" pos="0 0.015 -0.013" type="box" />
                              <body name="thumb_dip" pos="0 0.0145 -0.017" quat="0.707109 -0.707105 0 0">
                                <inertial pos="0 0 0" quat="0.708624 0.704906 0.00637342 0.0303153" mass="0.038" diaginertia="8.48742e-06 7.67823e-06 3.82835e-06" />
                                <joint name="14" class="leap_thumb" pos="0 0 0" axis="0 0 -1" range="-1.2 1.9" actuatorfrcrange="-0.95 0.95" />
                                <geom pos="0.0439 0.0579 -0.0086" quat="1 0 0 0" type="mesh" contype="0" conaffinity="0" group="1" density="0" mesh="thumb_dip" />
                                <geom size="0.01 0.02 0.012" pos="0 0.0105 -0.014" type="box" />
                                <geom size="0.01 0.002 0.016" pos="0 0.031 -0.015" type="box" />
                                <geom size="0.007 0.01 0.002" pos="0 0.042 0.001" type="box" />
                                <geom size="0.007 0.01 0.002" pos="0 0.042 -0.029" type="box" />
                                <geom size="0.005 0.012 0.009" pos="-0.0135 0.0175 -0.011656" type="box" />
                                <body name="thumb_fingertip" pos="0 0.0466 0.0002" quat="1.32679e-06 0 0 1">
                                  <inertial pos="0 0 0" quat="0.704307 0.709299 0.006848 -0.0282727" mass="0.049" diaginertia="2.03882e-05 1.98443e-05 4.32049e-06" />
                                  <joint name="15" class="leap_thumb" pos="0 0 0" axis="0 0 -1" range="-1.34 1.88" actuatorfrcrange="-0.95 0.95" />
                                  <geom pos="0.0625 0.0784 0.0489" quat="1 0 0 0" type="mesh" contype="0" conaffinity="0" group="1" density="0" mesh="thumb_fingertip" />
                                  <geom size="0.01 0.018 0.012" pos="0 -0.0085 -0.015" type="box" />
                                  <geom size="0.01 0.002 0.015" pos="0 -0.029 -0.014" type="box" />
                                  <geom size="0.004 0.012 0.009" pos="0.015 -0.0175 -0.0115" type="box" />
                                  <geom type="mesh" mesh="white_tip_thumb" />
                                  <body name="thumb_tip_head" pos="0 -0.06 -0.015" />
                                </body>
                              </body>
                            </body>
                          </body>
                        </body>
                      </body>
                    </body>
                  </body>
                </body>
              </body>
            </body>
          </body>
        </body>
      </body>
    </body>
  </worldbody>
  <!-- Position-servo PD via default classes (ur5e MJCF pattern):
         force = gainprm[0]*(ctrl - qpos) + biasprm[2]*qvel
       PD values are SSoT'd in the <default> block above:
         iiwa7_proximal (A1-A4): kp=3000 kd=600
         iiwa7_distal   (A5-A7): kp=750  kd=150
         leap           (0-15) : kp=2.5  kd=0.125 (forcerange ±0.95 N·m clip)
       NOTE: mujoco_simulator.yaml use_yaml_servo_gains 가 true 면 YAML servo
       블록이 런타임에 이 값을 덮어쓴다. 현재 false → MJCF 값이 활성.
       MANUAL: urdf_to_mjcf 재실행 시 이 actuator 블록은 bare <general/>로
       되돌아갑니다. 재생성 후 이 블록을 다시 박을 것 (robots/iiwa7_leap/README.md). -->
  <actuator>
    <general class="iiwa7_proximal" name="A1" joint="A1" ctrlrange="-2.9671 2.9671" />
    <general class="iiwa7_proximal" name="A2" joint="A2" ctrlrange="-2.0944 2.0944" />
    <general class="iiwa7_proximal" name="A3" joint="A3" ctrlrange="-2.9671 2.9671" />
    <general class="iiwa7_proximal" name="A4" joint="A4" ctrlrange="-2.0944 2.0944" />
    <general class="iiwa7_distal"   name="A5" joint="A5" ctrlrange="-2.9671 2.9671" />
    <general class="iiwa7_distal"   name="A6" joint="A6" ctrlrange="-2.0944 2.0944" />
    <general class="iiwa7_distal"   name="A7" joint="A7" ctrlrange="-3.0543 3.0543" />
    <general class="leap" name="0"  joint="0"  ctrlrange="-1.047 1.047" />
    <general class="leap" name="1"  joint="1"  ctrlrange="-0.314 2.23" />
    <general class="leap" name="2"  joint="2"  ctrlrange="-0.506 1.885" />
    <general class="leap" name="3"  joint="3"  ctrlrange="-0.366 2.042" />
    <general class="leap" name="4"  joint="4"  ctrlrange="-1.047 1.047" />
    <general class="leap" name="5"  joint="5"  ctrlrange="-0.314 2.23" />
    <general class="leap" name="6"  joint="6"  ctrlrange="-0.506 1.885" />
    <general class="leap" name="7"  joint="7"  ctrlrange="-0.366 2.042" />
    <general class="leap" name="8"  joint="8"  ctrlrange="-1.047 1.047" />
    <general class="leap" name="9"  joint="9"  ctrlrange="-0.314 2.23" />
    <general class="leap" name="10" joint="10" ctrlrange="-0.506 1.885" />
    <general class="leap" name="11" joint="11" ctrlrange="-0.366 2.042" />
    <general class="leap" name="12" joint="12" ctrlrange="-0.349 2.094" />
    <general class="leap" name="13" joint="13" ctrlrange="-0.47 2.443" />
    <general class="leap" name="14" joint="14" ctrlrange="-1.2 1.9" />
    <general class="leap" name="15" joint="15" ctrlrange="-1.34 1.88" />
  </actuator>

  <keyframe>
    <!-- "home" = elbow-up, non-singular task-space ready posture.
         qpos order (23) = MJCF joint declaration order:
           iiwa7: A1 A2 A3 A4 A5 A6 A7
           LEAP : 1 0 2 3 5 4 6 7 9 8 10 11 12 13 14 15
         ctrl order (23) = actuator declaration order:
           iiwa7: A1 A2 A3 A4 A5 A6 A7
           LEAP : 0 1 2 3 4 5 6 7 8 9 10 11 12 13 14 15
         iiwa7 [0, -0.7, 0, 1.4, 0, -0.7, 0] mirrors estop.arm_safe_position
         in integrated_bringup/config/iiwa7_leap/controllers/demo_*_controller.yaml,
         so sim spawn and controller bring-up agree on the first valid tick.
         LEAP fingers stay at 0 (fully extended, no hand singularity). -->
    <key name="home" qpos="0 0.7 0 -1.0 0 0.7 0   0 0 0 0 0 0 0 0 0 0 0 0 0 0 0 0"
                     ctrl="0 0.7 0 -1.0 0 0.7 0   0 0 0 0 0 0 0 0 0 0 0 0 0 0 0 0"/>
  </keyframe>

  <!-- Parent-child contact excludes intentionally removed (user request 2026-05-15).
       Previously this block excluded: iiwa7 arm chain, iiwa7↔LEAP junction,
       index/middle/ring/thumb finger chains, and *tip_head leaf bodies.
       Re-enable selectively if LEAP finger boxes show trembling against their
       parent links every tick. -->
</mujoco>
